13-May-23 09:17:42 - root - 85317 - INFO - Starting server...
13-May-23 09:17:42 - root - 85317 - INFO - Server thread started!
13-May-23 09:19:36 - root - 85344 - INFO - Starting server...
13-May-23 09:19:36 - root - 85344 - INFO - Preparing to client server on localhost:8080...
13-May-23 09:19:36 - root - 85344 - INFO - Server thread started!
13-May-23 09:19:36 - werkzeug - 85344 - INFO -  * Running on http://localhost:8080/ (Press CTRL+C to quit)
13-May-23 09:19:39 - werkzeug - 85344 - INFO - 127.0.0.1 - - [13/May/2023 09:19:39] "GET / HTTP/1.1" 200 -
13-May-23 09:19:40 - werkzeug - 85344 - INFO - 127.0.0.1 - - [13/May/2023 09:19:40] "GET /static/rspy.png HTTP/1.1" 200 -
13-May-23 09:19:40 - werkzeug - 85344 - INFO - 127.0.0.1 - - [13/May/2023 09:19:40] "[33mGET /favicon.ico HTTP/1.1[0m" 404 -
13-May-23 09:19:47 - root - 85344 - INFO - Preparing to send connect_data_request to localhost:40000...
13-May-23 09:19:47 - server - 85344 - ERROR - Exception on /connect [GET]
Traceback (most recent call last):
  File "/Users/Aiden/anaconda3/lib/python3.9/site-packages/flask/app.py", line 2447, in wsgi_app
    response = self.full_dispatch_request()
  File "/Users/Aiden/anaconda3/lib/python3.9/site-packages/flask/app.py", line 1952, in full_dispatch_request
    rv = self.handle_user_exception(e)
  File "/Users/Aiden/anaconda3/lib/python3.9/site-packages/flask/app.py", line 1821, in handle_user_exception
    reraise(exc_type, exc_value, tb)
  File "/Users/Aiden/anaconda3/lib/python3.9/site-packages/flask/_compat.py", line 39, in reraise
    raise value
  File "/Users/Aiden/anaconda3/lib/python3.9/site-packages/flask/app.py", line 1950, in full_dispatch_request
    rv = self.dispatch_request()
  File "/Users/Aiden/anaconda3/lib/python3.9/site-packages/flask/app.py", line 1936, in dispatch_request
    return self.view_functions[rule.endpoint](**req.view_args)
  File "/Users/Aiden/Desktop/B3rryClientServer/ClientSide/server.py", line 54, in connect
    request_data = json.dumps(request)
  File "/Users/Aiden/anaconda3/lib/python3.9/json/__init__.py", line 231, in dumps
    return _default_encoder.encode(obj)
  File "/Users/Aiden/anaconda3/lib/python3.9/json/encoder.py", line 199, in encode
    chunks = self.iterencode(o, _one_shot=True)
  File "/Users/Aiden/anaconda3/lib/python3.9/json/encoder.py", line 257, in iterencode
    return _iterencode(o, 0)
  File "/Users/Aiden/anaconda3/lib/python3.9/json/encoder.py", line 179, in default
    raise TypeError(f'Object of type {o.__class__.__name__} '
TypeError: Object of type Request is not JSON serializable
13-May-23 09:19:47 - werkzeug - 85344 - INFO - 127.0.0.1 - - [13/May/2023 09:19:47] "[35m[1mGET /connect?ip=localhost&port=40000 HTTP/1.1[0m" 500 -
13-May-23 09:21:30 - root - 85371 - INFO - Starting server...
13-May-23 09:21:30 - root - 85371 - INFO - Preparing to client server on localhost:8080...
13-May-23 09:21:30 - root - 85371 - INFO - Server thread started!
13-May-23 09:21:30 - werkzeug - 85371 - INFO -  * Running on http://localhost:8080/ (Press CTRL+C to quit)
13-May-23 09:21:33 - werkzeug - 85371 - INFO - 127.0.0.1 - - [13/May/2023 09:21:33] "GET / HTTP/1.1" 200 -
13-May-23 09:21:38 - root - 85371 - INFO - Preparing to send connect_data_request to localhost:40000...
13-May-23 09:21:38 - server - 85371 - ERROR - Exception on /connect [GET]
Traceback (most recent call last):
  File "/Users/Aiden/anaconda3/lib/python3.9/site-packages/flask/app.py", line 2447, in wsgi_app
    response = self.full_dispatch_request()
  File "/Users/Aiden/anaconda3/lib/python3.9/site-packages/flask/app.py", line 1952, in full_dispatch_request
    rv = self.handle_user_exception(e)
  File "/Users/Aiden/anaconda3/lib/python3.9/site-packages/flask/app.py", line 1821, in handle_user_exception
    reraise(exc_type, exc_value, tb)
  File "/Users/Aiden/anaconda3/lib/python3.9/site-packages/flask/_compat.py", line 39, in reraise
    raise value
  File "/Users/Aiden/anaconda3/lib/python3.9/site-packages/flask/app.py", line 1950, in full_dispatch_request
    rv = self.dispatch_request()
  File "/Users/Aiden/anaconda3/lib/python3.9/site-packages/flask/app.py", line 1936, in dispatch_request
    return self.view_functions[rule.endpoint](**req.view_args)
  File "/Users/Aiden/Desktop/B3rryClientServer/ClientSide/server.py", line 55, in connect
    self.telemetry_client.connect()
  File "/Users/Aiden/Desktop/B3rryClientServer/ClientSide/telemetryclient.py", line 46, in connect
    self.socket.connect((self.hostname, self.port))
TypeError: an integer is required (got type str)
13-May-23 09:21:38 - werkzeug - 85371 - INFO - 127.0.0.1 - - [13/May/2023 09:21:38] "[35m[1mGET /connect?ip=localhost&port=40000 HTTP/1.1[0m" 500 -
13-May-23 09:22:29 - root - 85381 - INFO - Starting server...
13-May-23 09:22:29 - root - 85381 - INFO - Preparing to client server on localhost:8080...
13-May-23 09:22:29 - root - 85381 - INFO - Server thread started!
13-May-23 09:22:29 - werkzeug - 85381 - INFO -  * Running on http://localhost:8080/ (Press CTRL+C to quit)
13-May-23 09:22:32 - werkzeug - 85381 - INFO - 127.0.0.1 - - [13/May/2023 09:22:32] "GET / HTTP/1.1" 200 -
13-May-23 09:22:37 - root - 85381 - INFO - Preparing to send connect_data_request to localhost:40000...
13-May-23 09:22:37 - server - 85381 - ERROR - Exception on /connect [GET]
Traceback (most recent call last):
  File "/Users/Aiden/anaconda3/lib/python3.9/site-packages/flask/app.py", line 2447, in wsgi_app
    response = self.full_dispatch_request()
  File "/Users/Aiden/anaconda3/lib/python3.9/site-packages/flask/app.py", line 1952, in full_dispatch_request
    rv = self.handle_user_exception(e)
  File "/Users/Aiden/anaconda3/lib/python3.9/site-packages/flask/app.py", line 1821, in handle_user_exception
    reraise(exc_type, exc_value, tb)
  File "/Users/Aiden/anaconda3/lib/python3.9/site-packages/flask/_compat.py", line 39, in reraise
    raise value
  File "/Users/Aiden/anaconda3/lib/python3.9/site-packages/flask/app.py", line 1950, in full_dispatch_request
    rv = self.dispatch_request()
  File "/Users/Aiden/anaconda3/lib/python3.9/site-packages/flask/app.py", line 1936, in dispatch_request
    return self.view_functions[rule.endpoint](**req.view_args)
  File "/Users/Aiden/Desktop/B3rryClientServer/ClientSide/server.py", line 55, in connect
    self.telemetry_client.connect()
  File "/Users/Aiden/Desktop/B3rryClientServer/ClientSide/telemetryclient.py", line 46, in connect
    self.socket.connect((self.hostname, self.port))
ConnectionRefusedError: [Errno 61] Connection refused
13-May-23 09:22:37 - werkzeug - 85381 - INFO - 127.0.0.1 - - [13/May/2023 09:22:37] "[35m[1mGET /connect?ip=localhost&port=40000 HTTP/1.1[0m" 500 -
13-May-23 09:22:57 - werkzeug - 85381 - INFO - 127.0.0.1 - - [13/May/2023 09:22:57] "GET / HTTP/1.1" 200 -
13-May-23 09:23:03 - root - 85381 - INFO - Preparing to send connect_data_request to 0.0.0.0:40000...
13-May-23 09:23:03 - server - 85381 - ERROR - Exception on /connect [GET]
Traceback (most recent call last):
  File "/Users/Aiden/anaconda3/lib/python3.9/site-packages/flask/app.py", line 2447, in wsgi_app
    response = self.full_dispatch_request()
  File "/Users/Aiden/anaconda3/lib/python3.9/site-packages/flask/app.py", line 1952, in full_dispatch_request
    rv = self.handle_user_exception(e)
  File "/Users/Aiden/anaconda3/lib/python3.9/site-packages/flask/app.py", line 1821, in handle_user_exception
    reraise(exc_type, exc_value, tb)
  File "/Users/Aiden/anaconda3/lib/python3.9/site-packages/flask/_compat.py", line 39, in reraise
    raise value
  File "/Users/Aiden/anaconda3/lib/python3.9/site-packages/flask/app.py", line 1950, in full_dispatch_request
    rv = self.dispatch_request()
  File "/Users/Aiden/anaconda3/lib/python3.9/site-packages/flask/app.py", line 1936, in dispatch_request
    return self.view_functions[rule.endpoint](**req.view_args)
  File "/Users/Aiden/Desktop/B3rryClientServer/ClientSide/server.py", line 55, in connect
    self.telemetry_client.connect()
  File "/Users/Aiden/Desktop/B3rryClientServer/ClientSide/telemetryclient.py", line 46, in connect
    self.socket.connect((self.hostname, self.port))
ConnectionRefusedError: [Errno 61] Connection refused
13-May-23 09:23:03 - werkzeug - 85381 - INFO - 127.0.0.1 - - [13/May/2023 09:23:03] "[35m[1mGET /connect?ip=0.0.0.0&port=40000 HTTP/1.1[0m" 500 -
13-May-23 09:23:44 - root - 85410 - INFO - Starting server...
13-May-23 09:23:44 - root - 85410 - INFO - Preparing to client server on localhost:8080...
13-May-23 09:23:44 - root - 85410 - INFO - Server thread started!
13-May-23 09:23:44 - werkzeug - 85410 - INFO -  * Running on http://localhost:8080/ (Press CTRL+C to quit)
13-May-23 09:23:52 - werkzeug - 85410 - INFO - 127.0.0.1 - - [13/May/2023 09:23:52] "GET / HTTP/1.1" 200 -
13-May-23 09:24:00 - root - 85410 - INFO - Preparing to send connect_data_request to localhost:40000...
13-May-23 09:24:00 - server - 85410 - ERROR - Exception on /connect [GET]
Traceback (most recent call last):
  File "/Users/Aiden/anaconda3/lib/python3.9/site-packages/flask/app.py", line 2447, in wsgi_app
    response = self.full_dispatch_request()
  File "/Users/Aiden/anaconda3/lib/python3.9/site-packages/flask/app.py", line 1952, in full_dispatch_request
    rv = self.handle_user_exception(e)
  File "/Users/Aiden/anaconda3/lib/python3.9/site-packages/flask/app.py", line 1821, in handle_user_exception
    reraise(exc_type, exc_value, tb)
  File "/Users/Aiden/anaconda3/lib/python3.9/site-packages/flask/_compat.py", line 39, in reraise
    raise value
  File "/Users/Aiden/anaconda3/lib/python3.9/site-packages/flask/app.py", line 1950, in full_dispatch_request
    rv = self.dispatch_request()
  File "/Users/Aiden/anaconda3/lib/python3.9/site-packages/flask/app.py", line 1936, in dispatch_request
    return self.view_functions[rule.endpoint](**req.view_args)
  File "/Users/Aiden/Desktop/B3rryClientServer/ClientSide/server.py", line 55, in connect
    self.telemetry_client.connect()
  File "/Users/Aiden/Desktop/B3rryClientServer/ClientSide/telemetryclient.py", line 46, in connect
    self.socket.connect((self.hostname, self.port))
ConnectionRefusedError: [Errno 61] Connection refused
13-May-23 09:24:00 - werkzeug - 85410 - INFO - 127.0.0.1 - - [13/May/2023 09:24:00] "[35m[1mGET /connect?ip=localhost&port=40000 HTTP/1.1[0m" 500 -
13-May-23 09:26:25 - root - 85410 - INFO - Preparing to send connect_data_request to localhost:40000...
13-May-23 09:26:25 - server - 85410 - ERROR - Exception on /connect [GET]
Traceback (most recent call last):
  File "/Users/Aiden/anaconda3/lib/python3.9/site-packages/flask/app.py", line 2447, in wsgi_app
    response = self.full_dispatch_request()
  File "/Users/Aiden/anaconda3/lib/python3.9/site-packages/flask/app.py", line 1952, in full_dispatch_request
    rv = self.handle_user_exception(e)
  File "/Users/Aiden/anaconda3/lib/python3.9/site-packages/flask/app.py", line 1821, in handle_user_exception
    reraise(exc_type, exc_value, tb)
  File "/Users/Aiden/anaconda3/lib/python3.9/site-packages/flask/_compat.py", line 39, in reraise
    raise value
  File "/Users/Aiden/anaconda3/lib/python3.9/site-packages/flask/app.py", line 1950, in full_dispatch_request
    rv = self.dispatch_request()
  File "/Users/Aiden/anaconda3/lib/python3.9/site-packages/flask/app.py", line 1936, in dispatch_request
    return self.view_functions[rule.endpoint](**req.view_args)
  File "/Users/Aiden/Desktop/B3rryClientServer/ClientSide/server.py", line 55, in connect
    self.telemetry_client.connect()
  File "/Users/Aiden/Desktop/B3rryClientServer/ClientSide/telemetryclient.py", line 46, in connect
    self.socket.connect((self.hostname, self.port))
ConnectionRefusedError: [Errno 61] Connection refused
13-May-23 09:26:25 - werkzeug - 85410 - INFO - 127.0.0.1 - - [13/May/2023 09:26:25] "[35m[1mGET /connect?ip=localhost&port=40000 HTTP/1.1[0m" 500 -
13-May-23 09:35:08 - root - 85551 - INFO - Starting server...
13-May-23 09:35:08 - root - 85551 - INFO - Preparing to client server on localhost:8080...
13-May-23 09:35:08 - root - 85551 - INFO - Server thread started!
13-May-23 09:35:08 - werkzeug - 85551 - INFO -  * Running on http://localhost:8080/ (Press CTRL+C to quit)
13-May-23 09:35:10 - werkzeug - 85551 - INFO - 127.0.0.1 - - [13/May/2023 09:35:10] "GET / HTTP/1.1" 200 -
13-May-23 09:35:16 - root - 85551 - INFO - Preparing to send connect_data_request to localhost:40000...
13-May-23 09:35:16 - server - 85551 - ERROR - Exception on /connect [GET]
Traceback (most recent call last):
  File "/Users/Aiden/anaconda3/lib/python3.9/site-packages/flask/app.py", line 2447, in wsgi_app
    response = self.full_dispatch_request()
  File "/Users/Aiden/anaconda3/lib/python3.9/site-packages/flask/app.py", line 1952, in full_dispatch_request
    rv = self.handle_user_exception(e)
  File "/Users/Aiden/anaconda3/lib/python3.9/site-packages/flask/app.py", line 1821, in handle_user_exception
    reraise(exc_type, exc_value, tb)
  File "/Users/Aiden/anaconda3/lib/python3.9/site-packages/flask/_compat.py", line 39, in reraise
    raise value
  File "/Users/Aiden/anaconda3/lib/python3.9/site-packages/flask/app.py", line 1950, in full_dispatch_request
    rv = self.dispatch_request()
  File "/Users/Aiden/anaconda3/lib/python3.9/site-packages/flask/app.py", line 1936, in dispatch_request
    return self.view_functions[rule.endpoint](**req.view_args)
  File "/Users/Aiden/Desktop/B3rryClientServer/ClientSide/server.py", line 55, in connect
    self.telemetry_client.connect()
  File "/Users/Aiden/Desktop/B3rryClientServer/ClientSide/telemetryclient.py", line 46, in connect
    self.socket.connect((self.hostname, self.port))
ConnectionRefusedError: [Errno 61] Connection refused
13-May-23 09:35:16 - werkzeug - 85551 - INFO - 127.0.0.1 - - [13/May/2023 09:35:16] "[35m[1mGET /connect?ip=localhost&port=40000 HTTP/1.1[0m" 500 -
13-May-23 09:36:18 - root - 85571 - INFO - Starting server...
13-May-23 09:36:18 - root - 85571 - INFO - Preparing to client server on localhost:8080...
13-May-23 09:36:18 - root - 85571 - INFO - Server thread started!
13-May-23 09:36:18 - werkzeug - 85571 - INFO -  * Running on http://localhost:8080/ (Press CTRL+C to quit)
13-May-23 09:36:26 - werkzeug - 85571 - INFO - 127.0.0.1 - - [13/May/2023 09:36:26] "GET / HTTP/1.1" 200 -
13-May-23 09:36:28 - root - 85571 - INFO - Preparing to send connect_data_request to localhost:40000...
13-May-23 09:36:28 - server - 85571 - ERROR - Exception on /connect [GET]
Traceback (most recent call last):
  File "/Users/Aiden/anaconda3/lib/python3.9/site-packages/flask/app.py", line 2447, in wsgi_app
    response = self.full_dispatch_request()
  File "/Users/Aiden/anaconda3/lib/python3.9/site-packages/flask/app.py", line 1952, in full_dispatch_request
    rv = self.handle_user_exception(e)
  File "/Users/Aiden/anaconda3/lib/python3.9/site-packages/flask/app.py", line 1821, in handle_user_exception
    reraise(exc_type, exc_value, tb)
  File "/Users/Aiden/anaconda3/lib/python3.9/site-packages/flask/_compat.py", line 39, in reraise
    raise value
  File "/Users/Aiden/anaconda3/lib/python3.9/site-packages/flask/app.py", line 1950, in full_dispatch_request
    rv = self.dispatch_request()
  File "/Users/Aiden/anaconda3/lib/python3.9/site-packages/flask/app.py", line 1936, in dispatch_request
    return self.view_functions[rule.endpoint](**req.view_args)
  File "/Users/Aiden/Desktop/B3rryClientServer/ClientSide/server.py", line 55, in connect
    self.telemetry_client.connect()
  File "/Users/Aiden/Desktop/B3rryClientServer/ClientSide/telemetryclient.py", line 46, in connect
    self.socket.connect((self.hostname, self.port))
ConnectionRefusedError: [Errno 61] Connection refused
13-May-23 09:36:28 - werkzeug - 85571 - INFO - 127.0.0.1 - - [13/May/2023 09:36:28] "[35m[1mGET /connect?ip=localhost&port=40000 HTTP/1.1[0m" 500 -
13-May-23 09:39:49 - root - 85670 - INFO - Starting server...
13-May-23 09:39:49 - root - 85670 - INFO - Preparing to client server on localhost:8080...
13-May-23 09:39:49 - root - 85670 - INFO - Server thread started!
13-May-23 09:39:49 - werkzeug - 85670 - INFO -  * Running on http://localhost:8080/ (Press CTRL+C to quit)
13-May-23 09:39:52 - root - 85670 - INFO - Preparing to send connect_data_request to localhost:40000...
13-May-23 09:39:52 - server - 85670 - ERROR - Exception on /connect [GET]
Traceback (most recent call last):
  File "/Users/Aiden/anaconda3/lib/python3.9/site-packages/flask/app.py", line 2447, in wsgi_app
    response = self.full_dispatch_request()
  File "/Users/Aiden/anaconda3/lib/python3.9/site-packages/flask/app.py", line 1952, in full_dispatch_request
    rv = self.handle_user_exception(e)
  File "/Users/Aiden/anaconda3/lib/python3.9/site-packages/flask/app.py", line 1821, in handle_user_exception
    reraise(exc_type, exc_value, tb)
  File "/Users/Aiden/anaconda3/lib/python3.9/site-packages/flask/_compat.py", line 39, in reraise
    raise value
  File "/Users/Aiden/anaconda3/lib/python3.9/site-packages/flask/app.py", line 1950, in full_dispatch_request
    rv = self.dispatch_request()
  File "/Users/Aiden/anaconda3/lib/python3.9/site-packages/flask/app.py", line 1936, in dispatch_request
    return self.view_functions[rule.endpoint](**req.view_args)
  File "/Users/Aiden/Desktop/B3rryClientServer/ClientSide/server.py", line 55, in connect
    self.telemetry_client.connect()
  File "/Users/Aiden/Desktop/B3rryClientServer/ClientSide/telemetryclient.py", line 46, in connect
    self.socket.connect((self.hostname, self.port))
ConnectionRefusedError: [Errno 61] Connection refused
13-May-23 09:39:52 - werkzeug - 85670 - INFO - 127.0.0.1 - - [13/May/2023 09:39:52] "[35m[1mGET /connect?ip=localhost&port=40000 HTTP/1.1[0m" 500 -
13-May-23 09:39:54 - root - 85670 - INFO - Preparing to send connect_data_request to localhost:40000...
13-May-23 09:39:54 - server - 85670 - ERROR - Exception on /connect [GET]
Traceback (most recent call last):
  File "/Users/Aiden/anaconda3/lib/python3.9/site-packages/flask/app.py", line 2447, in wsgi_app
    response = self.full_dispatch_request()
  File "/Users/Aiden/anaconda3/lib/python3.9/site-packages/flask/app.py", line 1952, in full_dispatch_request
    rv = self.handle_user_exception(e)
  File "/Users/Aiden/anaconda3/lib/python3.9/site-packages/flask/app.py", line 1821, in handle_user_exception
    reraise(exc_type, exc_value, tb)
  File "/Users/Aiden/anaconda3/lib/python3.9/site-packages/flask/_compat.py", line 39, in reraise
    raise value
  File "/Users/Aiden/anaconda3/lib/python3.9/site-packages/flask/app.py", line 1950, in full_dispatch_request
    rv = self.dispatch_request()
  File "/Users/Aiden/anaconda3/lib/python3.9/site-packages/flask/app.py", line 1936, in dispatch_request
    return self.view_functions[rule.endpoint](**req.view_args)
  File "/Users/Aiden/Desktop/B3rryClientServer/ClientSide/server.py", line 55, in connect
    self.telemetry_client.connect()
  File "/Users/Aiden/Desktop/B3rryClientServer/ClientSide/telemetryclient.py", line 46, in connect
    self.socket.connect((self.hostname, self.port))
ConnectionRefusedError: [Errno 61] Connection refused
13-May-23 09:39:54 - werkzeug - 85670 - INFO - 127.0.0.1 - - [13/May/2023 09:39:54] "[35m[1mGET /connect?ip=localhost&port=40000 HTTP/1.1[0m" 500 -
13-May-23 09:42:21 - root - 85698 - INFO - Starting server...
13-May-23 09:42:21 - root - 85698 - INFO - Preparing to client server on localhost:8080...
13-May-23 09:42:21 - root - 85698 - INFO - Server thread started!
13-May-23 09:42:21 - werkzeug - 85698 - INFO -  * Running on http://localhost:8080/ (Press CTRL+C to quit)
13-May-23 09:42:25 - root - 85698 - INFO - Preparing to send connect_data_request to localhost:40000...
13-May-23 09:42:25 - server - 85698 - ERROR - Exception on /connect [GET]
Traceback (most recent call last):
  File "/Users/Aiden/anaconda3/lib/python3.9/site-packages/flask/app.py", line 2447, in wsgi_app
    response = self.full_dispatch_request()
  File "/Users/Aiden/anaconda3/lib/python3.9/site-packages/flask/app.py", line 1952, in full_dispatch_request
    rv = self.handle_user_exception(e)
  File "/Users/Aiden/anaconda3/lib/python3.9/site-packages/flask/app.py", line 1821, in handle_user_exception
    reraise(exc_type, exc_value, tb)
  File "/Users/Aiden/anaconda3/lib/python3.9/site-packages/flask/_compat.py", line 39, in reraise
    raise value
  File "/Users/Aiden/anaconda3/lib/python3.9/site-packages/flask/app.py", line 1950, in full_dispatch_request
    rv = self.dispatch_request()
  File "/Users/Aiden/anaconda3/lib/python3.9/site-packages/flask/app.py", line 1936, in dispatch_request
    return self.view_functions[rule.endpoint](**req.view_args)
  File "/Users/Aiden/Desktop/B3rryClientServer/ClientSide/server.py", line 55, in connect
    self.telemetry_client.connect()
  File "/Users/Aiden/Desktop/B3rryClientServer/ClientSide/telemetryclient.py", line 46, in connect
    self.socket.connect((self.hostname, self.port))
ConnectionRefusedError: [Errno 61] Connection refused
13-May-23 09:42:25 - werkzeug - 85698 - INFO - 127.0.0.1 - - [13/May/2023 09:42:25] "[35m[1mGET /connect?ip=localhost&port=40000 HTTP/1.1[0m" 500 -
13-May-23 09:42:26 - root - 85698 - INFO - Preparing to send connect_data_request to localhost:40000...
13-May-23 09:42:26 - server - 85698 - ERROR - Exception on /connect [GET]
Traceback (most recent call last):
  File "/Users/Aiden/anaconda3/lib/python3.9/site-packages/flask/app.py", line 2447, in wsgi_app
    response = self.full_dispatch_request()
  File "/Users/Aiden/anaconda3/lib/python3.9/site-packages/flask/app.py", line 1952, in full_dispatch_request
    rv = self.handle_user_exception(e)
  File "/Users/Aiden/anaconda3/lib/python3.9/site-packages/flask/app.py", line 1821, in handle_user_exception
    reraise(exc_type, exc_value, tb)
  File "/Users/Aiden/anaconda3/lib/python3.9/site-packages/flask/_compat.py", line 39, in reraise
    raise value
  File "/Users/Aiden/anaconda3/lib/python3.9/site-packages/flask/app.py", line 1950, in full_dispatch_request
    rv = self.dispatch_request()
  File "/Users/Aiden/anaconda3/lib/python3.9/site-packages/flask/app.py", line 1936, in dispatch_request
    return self.view_functions[rule.endpoint](**req.view_args)
  File "/Users/Aiden/Desktop/B3rryClientServer/ClientSide/server.py", line 55, in connect
    self.telemetry_client.connect()
  File "/Users/Aiden/Desktop/B3rryClientServer/ClientSide/telemetryclient.py", line 46, in connect
    self.socket.connect((self.hostname, self.port))
ConnectionRefusedError: [Errno 61] Connection refused
13-May-23 09:42:26 - werkzeug - 85698 - INFO - 127.0.0.1 - - [13/May/2023 09:42:26] "[35m[1mGET /connect?ip=localhost&port=40000 HTTP/1.1[0m" 500 -
13-May-23 09:45:38 - root - 85729 - INFO - Starting server...
13-May-23 09:45:38 - root - 85729 - INFO - Preparing to client server on localhost:8080...
13-May-23 09:45:38 - root - 85729 - INFO - Server thread started!
13-May-23 09:45:38 - werkzeug - 85729 - INFO -  * Running on http://localhost:8080/ (Press CTRL+C to quit)
13-May-23 09:45:41 - werkzeug - 85729 - INFO - 127.0.0.1 - - [13/May/2023 09:45:41] "GET / HTTP/1.1" 200 -
13-May-23 09:45:46 - root - 85729 - INFO - Preparing to send connect_data_request to localhost:40000...
13-May-23 09:45:46 - server - 85729 - ERROR - Exception on /connect [GET]
Traceback (most recent call last):
  File "/Users/Aiden/anaconda3/lib/python3.9/site-packages/flask/app.py", line 2447, in wsgi_app
    response = self.full_dispatch_request()
  File "/Users/Aiden/anaconda3/lib/python3.9/site-packages/flask/app.py", line 1952, in full_dispatch_request
    rv = self.handle_user_exception(e)
  File "/Users/Aiden/anaconda3/lib/python3.9/site-packages/flask/app.py", line 1821, in handle_user_exception
    reraise(exc_type, exc_value, tb)
  File "/Users/Aiden/anaconda3/lib/python3.9/site-packages/flask/_compat.py", line 39, in reraise
    raise value
  File "/Users/Aiden/anaconda3/lib/python3.9/site-packages/flask/app.py", line 1950, in full_dispatch_request
    rv = self.dispatch_request()
  File "/Users/Aiden/anaconda3/lib/python3.9/site-packages/flask/app.py", line 1936, in dispatch_request
    return self.view_functions[rule.endpoint](**req.view_args)
  File "/Users/Aiden/Desktop/B3rryClientServer/ClientSide/server.py", line 55, in connect
    self.telemetry_client.connect()
  File "/Users/Aiden/Desktop/B3rryClientServer/ClientSide/telemetryclient.py", line 46, in connect
    self.socket.connect((self.hostname, self.port))
ConnectionRefusedError: [Errno 61] Connection refused
13-May-23 09:45:46 - werkzeug - 85729 - INFO - 127.0.0.1 - - [13/May/2023 09:45:46] "[35m[1mGET /connect?ip=localhost&port=40000 HTTP/1.1[0m" 500 -
13-May-23 09:47:53 - root - 85778 - INFO - Starting server...
13-May-23 09:47:53 - root - 85778 - INFO - Preparing to client server on localhost:8080...
13-May-23 09:47:53 - root - 85778 - INFO - Server thread started!
13-May-23 09:47:53 - werkzeug - 85778 - INFO -  * Running on http://localhost:8080/ (Press CTRL+C to quit)
13-May-23 09:47:56 - werkzeug - 85778 - INFO - 127.0.0.1 - - [13/May/2023 09:47:56] "GET / HTTP/1.1" 200 -
13-May-23 09:48:00 - root - 85778 - INFO - Preparing to send connect_data_request to loc:40000...
13-May-23 09:48:00 - server - 85778 - ERROR - Exception on /connect [GET]
Traceback (most recent call last):
  File "/Users/Aiden/anaconda3/lib/python3.9/site-packages/flask/app.py", line 2447, in wsgi_app
    response = self.full_dispatch_request()
  File "/Users/Aiden/anaconda3/lib/python3.9/site-packages/flask/app.py", line 1952, in full_dispatch_request
    rv = self.handle_user_exception(e)
  File "/Users/Aiden/anaconda3/lib/python3.9/site-packages/flask/app.py", line 1821, in handle_user_exception
    reraise(exc_type, exc_value, tb)
  File "/Users/Aiden/anaconda3/lib/python3.9/site-packages/flask/_compat.py", line 39, in reraise
    raise value
  File "/Users/Aiden/anaconda3/lib/python3.9/site-packages/flask/app.py", line 1950, in full_dispatch_request
    rv = self.dispatch_request()
  File "/Users/Aiden/anaconda3/lib/python3.9/site-packages/flask/app.py", line 1936, in dispatch_request
    return self.view_functions[rule.endpoint](**req.view_args)
  File "/Users/Aiden/Desktop/B3rryClientServer/ClientSide/server.py", line 55, in connect
    self.telemetry_client.connect()
  File "/Users/Aiden/Desktop/B3rryClientServer/ClientSide/telemetryclient.py", line 46, in connect
    self.socket.connect((self.hostname, self.port))
socket.gaierror: [Errno 8] nodename nor servname provided, or not known
13-May-23 09:48:00 - werkzeug - 85778 - INFO - 127.0.0.1 - - [13/May/2023 09:48:00] "[35m[1mGET /connect?ip=loc&port=40000 HTTP/1.1[0m" 500 -
13-May-23 09:48:07 - werkzeug - 85778 - INFO - 127.0.0.1 - - [13/May/2023 09:48:07] "GET / HTTP/1.1" 200 -
13-May-23 09:48:11 - root - 85778 - INFO - Preparing to send connect_data_request to localhost:40000...
13-May-23 09:48:11 - server - 85778 - ERROR - Exception on /connect [GET]
Traceback (most recent call last):
  File "/Users/Aiden/anaconda3/lib/python3.9/site-packages/flask/app.py", line 2447, in wsgi_app
    response = self.full_dispatch_request()
  File "/Users/Aiden/anaconda3/lib/python3.9/site-packages/flask/app.py", line 1952, in full_dispatch_request
    rv = self.handle_user_exception(e)
  File "/Users/Aiden/anaconda3/lib/python3.9/site-packages/flask/app.py", line 1821, in handle_user_exception
    reraise(exc_type, exc_value, tb)
  File "/Users/Aiden/anaconda3/lib/python3.9/site-packages/flask/_compat.py", line 39, in reraise
    raise value
  File "/Users/Aiden/anaconda3/lib/python3.9/site-packages/flask/app.py", line 1950, in full_dispatch_request
    rv = self.dispatch_request()
  File "/Users/Aiden/anaconda3/lib/python3.9/site-packages/flask/app.py", line 1936, in dispatch_request
    return self.view_functions[rule.endpoint](**req.view_args)
  File "/Users/Aiden/Desktop/B3rryClientServer/ClientSide/server.py", line 55, in connect
    self.telemetry_client.connect()
  File "/Users/Aiden/Desktop/B3rryClientServer/ClientSide/telemetryclient.py", line 46, in connect
    self.socket.connect((self.hostname, self.port))
ConnectionRefusedError: [Errno 61] Connection refused
13-May-23 09:48:11 - werkzeug - 85778 - INFO - 127.0.0.1 - - [13/May/2023 09:48:11] "[35m[1mGET /connect?ip=localhost&port=40000 HTTP/1.1[0m" 500 -
13-May-23 09:48:22 - root - 85778 - INFO - Preparing to send connect_data_request to localhost:40000...
13-May-23 09:48:22 - server - 85778 - ERROR - Exception on /connect [GET]
Traceback (most recent call last):
  File "/Users/Aiden/anaconda3/lib/python3.9/site-packages/flask/app.py", line 2447, in wsgi_app
    response = self.full_dispatch_request()
  File "/Users/Aiden/anaconda3/lib/python3.9/site-packages/flask/app.py", line 1952, in full_dispatch_request
    rv = self.handle_user_exception(e)
  File "/Users/Aiden/anaconda3/lib/python3.9/site-packages/flask/app.py", line 1821, in handle_user_exception
    reraise(exc_type, exc_value, tb)
  File "/Users/Aiden/anaconda3/lib/python3.9/site-packages/flask/_compat.py", line 39, in reraise
    raise value
  File "/Users/Aiden/anaconda3/lib/python3.9/site-packages/flask/app.py", line 1950, in full_dispatch_request
    rv = self.dispatch_request()
  File "/Users/Aiden/anaconda3/lib/python3.9/site-packages/flask/app.py", line 1936, in dispatch_request
    return self.view_functions[rule.endpoint](**req.view_args)
  File "/Users/Aiden/Desktop/B3rryClientServer/ClientSide/server.py", line 55, in connect
    self.telemetry_client.connect()
  File "/Users/Aiden/Desktop/B3rryClientServer/ClientSide/telemetryclient.py", line 46, in connect
    self.socket.connect((self.hostname, self.port))
ConnectionRefusedError: [Errno 61] Connection refused
13-May-23 09:48:22 - werkzeug - 85778 - INFO - 127.0.0.1 - - [13/May/2023 09:48:22] "[35m[1mGET /connect?ip=localhost&port=40000 HTTP/1.1[0m" 500 -
13-May-23 09:50:05 - root - 85835 - INFO - Starting server...
13-May-23 09:50:05 - root - 85835 - INFO - Preparing to client server on localhost:8080...
13-May-23 09:50:05 - root - 85835 - INFO - Server thread started!
13-May-23 09:50:05 - werkzeug - 85835 - INFO -  * Running on http://localhost:8080/ (Press CTRL+C to quit)
13-May-23 09:50:07 - werkzeug - 85835 - INFO - 127.0.0.1 - - [13/May/2023 09:50:07] "GET / HTTP/1.1" 200 -
13-May-23 09:50:12 - root - 85835 - INFO - Preparing to send connect_data_request to localhost:40000...
13-May-23 09:50:12 - server - 85835 - ERROR - Exception on /connect [GET]
Traceback (most recent call last):
  File "/Users/Aiden/anaconda3/lib/python3.9/site-packages/flask/app.py", line 2447, in wsgi_app
    response = self.full_dispatch_request()
  File "/Users/Aiden/anaconda3/lib/python3.9/site-packages/flask/app.py", line 1952, in full_dispatch_request
    rv = self.handle_user_exception(e)
  File "/Users/Aiden/anaconda3/lib/python3.9/site-packages/flask/app.py", line 1821, in handle_user_exception
    reraise(exc_type, exc_value, tb)
  File "/Users/Aiden/anaconda3/lib/python3.9/site-packages/flask/_compat.py", line 39, in reraise
    raise value
  File "/Users/Aiden/anaconda3/lib/python3.9/site-packages/flask/app.py", line 1950, in full_dispatch_request
    rv = self.dispatch_request()
  File "/Users/Aiden/anaconda3/lib/python3.9/site-packages/flask/app.py", line 1936, in dispatch_request
    return self.view_functions[rule.endpoint](**req.view_args)
  File "/Users/Aiden/Desktop/B3rryClientServer/ClientSide/server.py", line 56, in connect
    telemetry = self.telemetry_client.request_telemetry(bytes(request_data), 5)
TypeError: string argument without an encoding
13-May-23 09:50:12 - werkzeug - 85835 - INFO - 127.0.0.1 - - [13/May/2023 09:50:12] "[35m[1mGET /connect?ip=localhost&port=40000 HTTP/1.1[0m" 500 -
13-May-23 09:51:05 - root - 85847 - INFO - Starting server...
13-May-23 09:51:05 - root - 85847 - INFO - Preparing to client server on localhost:8080...
13-May-23 09:51:05 - root - 85847 - INFO - Server thread started!
13-May-23 09:51:05 - werkzeug - 85847 - INFO -  * Running on http://localhost:8080/ (Press CTRL+C to quit)
13-May-23 09:51:08 - werkzeug - 85847 - INFO - 127.0.0.1 - - [13/May/2023 09:51:08] "GET / HTTP/1.1" 200 -
13-May-23 09:51:13 - root - 85847 - INFO - Preparing to send connect_data_request to localhost:40000...
13-May-23 09:51:13 - werkzeug - 85847 - INFO - 127.0.0.1 - - [13/May/2023 09:51:13] "GET /connect?ip=localhost&port=40000 HTTP/1.1" 200 -
13-May-23 09:57:29 - root - 85943 - INFO - Starting server...
13-May-23 09:57:29 - root - 85943 - INFO - Preparing to client server on localhost:8080...
13-May-23 09:57:29 - root - 85943 - INFO - Server thread started!
13-May-23 09:57:29 - werkzeug - 85943 - INFO -  * Running on http://localhost:8080/ (Press CTRL+C to quit)
13-May-23 09:57:34 - werkzeug - 85943 - INFO - 127.0.0.1 - - [13/May/2023 09:57:34] "GET / HTTP/1.1" 200 -
13-May-23 09:57:39 - root - 85943 - INFO - Preparing to send connect_data_request to localhost:40000...
13-May-23 09:57:39 - werkzeug - 85943 - INFO - 127.0.0.1 - - [13/May/2023 09:57:39] "GET /connect?ip=localhost&port=40000 HTTP/1.1" 200 -
13-May-23 10:04:51 - root - 86258 - INFO - Starting server...
13-May-23 10:04:51 - root - 86258 - INFO - Preparing to client server on localhost:8080...
13-May-23 10:04:51 - root - 86258 - INFO - Server thread started!
13-May-23 10:04:51 - werkzeug - 86258 - INFO -  * Running on http://localhost:8080/ (Press CTRL+C to quit)
13-May-23 10:04:59 - werkzeug - 86258 - INFO - 127.0.0.1 - - [13/May/2023 10:04:59] "GET / HTTP/1.1" 200 -
13-May-23 10:05:05 - root - 86258 - INFO - Preparing to send connect_data_request to localhost:40000...
13-May-23 10:05:05 - werkzeug - 86258 - INFO - 127.0.0.1 - - [13/May/2023 10:05:05] "GET /connect?ip=localhost&port=40000 HTTP/1.1" 200 -
13-May-23 15:45:14 - root - 87110 - INFO - Starting server...
13-May-23 15:45:14 - root - 87110 - INFO - Preparing to client server on localhost:8080...
13-May-23 15:45:14 - root - 87110 - INFO - Server thread started!
13-May-23 15:45:14 - werkzeug - 87110 - INFO -  * Running on http://localhost:8080/ (Press CTRL+C to quit)
13-May-23 15:45:20 - werkzeug - 87110 - INFO - 127.0.0.1 - - [13/May/2023 15:45:20] "GET / HTTP/1.1" 200 -
13-May-23 15:45:27 - root - 87110 - INFO - Preparing to send connect_data_request to localhost:40000...
13-May-23 15:45:27 - werkzeug - 87110 - INFO - 127.0.0.1 - - [13/May/2023 15:45:27] "GET /connect?ip=localhost&port=40000 HTTP/1.1" 200 -
13-May-23 15:45:27 - werkzeug - 87110 - INFO - 127.0.0.1 - - [13/May/2023 15:45:27] "GET /static/nipplejs.min.js HTTP/1.1" 200 -
13-May-23 15:45:32 - root - 87110 - INFO - {'x': 0, 'y': 0}
13-May-23 15:45:32 - root - 87110 - INFO - {'left': 0, 'right': 0}
13-May-23 15:45:32 - root - 87110 - INFO - {'x': 5, 'y': -4}
13-May-23 15:45:32 - server - 87110 - ERROR - Exception on /joystick [GET]
Traceback (most recent call last):
  File "/Users/Aiden/anaconda3/lib/python3.9/site-packages/flask/app.py", line 2447, in wsgi_app
    response = self.full_dispatch_request()
  File "/Users/Aiden/anaconda3/lib/python3.9/site-packages/flask/app.py", line 1952, in full_dispatch_request
    rv = self.handle_user_exception(e)
  File "/Users/Aiden/anaconda3/lib/python3.9/site-packages/flask/app.py", line 1821, in handle_user_exception
    reraise(exc_type, exc_value, tb)
  File "/Users/Aiden/anaconda3/lib/python3.9/site-packages/flask/_compat.py", line 39, in reraise
    raise value
  File "/Users/Aiden/anaconda3/lib/python3.9/site-packages/flask/app.py", line 1950, in full_dispatch_request
    rv = self.dispatch_request()
  File "/Users/Aiden/anaconda3/lib/python3.9/site-packages/flask/app.py", line 1936, in dispatch_request
    return self.view_functions[rule.endpoint](**req.view_args)
  File "/Users/Aiden/Desktop/B3rryClientServer/ClientSide/server.py", line 80, in joystick
    self.motor_handler.send_motor_data(bytes(data, "utf-8"))
  File "/Users/Aiden/Desktop/B3rryClientServer/ClientSide/motorfrontend.py", line 62, in send_motor_data
    self.command_pipe.send(data)
  File "/Users/Aiden/Desktop/B3rryClientServer/ClientSide/cmdpipe.py", line 56, in send
    raise NotConnected("You must run Transmitter.connect() before attempting to send data.")
cmdpipe.NotConnected: You must run Transmitter.connect() before attempting to send data.
13-May-23 15:45:32 - root - 87110 - INFO - {'left': -1, 'right': 3}
13-May-23 15:45:32 - werkzeug - 87110 - INFO - 127.0.0.1 - - [13/May/2023 15:45:32] "[35m[1mGET /joystick?data={%22x%22:0,%22y%22:0} HTTP/1.1[0m" 500 -
13-May-23 15:45:32 - server - 87110 - ERROR - Exception on /joystick [GET]
Traceback (most recent call last):
  File "/Users/Aiden/anaconda3/lib/python3.9/site-packages/flask/app.py", line 2447, in wsgi_app
    response = self.full_dispatch_request()
  File "/Users/Aiden/anaconda3/lib/python3.9/site-packages/flask/app.py", line 1952, in full_dispatch_request
    rv = self.handle_user_exception(e)
  File "/Users/Aiden/anaconda3/lib/python3.9/site-packages/flask/app.py", line 1821, in handle_user_exception
    reraise(exc_type, exc_value, tb)
  File "/Users/Aiden/anaconda3/lib/python3.9/site-packages/flask/_compat.py", line 39, in reraise
    raise value
  File "/Users/Aiden/anaconda3/lib/python3.9/site-packages/flask/app.py", line 1950, in full_dispatch_request
    rv = self.dispatch_request()
  File "/Users/Aiden/anaconda3/lib/python3.9/site-packages/flask/app.py", line 1936, in dispatch_request
    return self.view_functions[rule.endpoint](**req.view_args)
  File "/Users/Aiden/Desktop/B3rryClientServer/ClientSide/server.py", line 80, in joystick
    self.motor_handler.send_motor_data(bytes(data, "utf-8"))
  File "/Users/Aiden/Desktop/B3rryClientServer/ClientSide/motorfrontend.py", line 62, in send_motor_data
    self.command_pipe.send(data)
  File "/Users/Aiden/Desktop/B3rryClientServer/ClientSide/cmdpipe.py", line 56, in send
    raise NotConnected("You must run Transmitter.connect() before attempting to send data.")
cmdpipe.NotConnected: You must run Transmitter.connect() before attempting to send data.
13-May-23 15:45:32 - werkzeug - 87110 - INFO - 127.0.0.1 - - [13/May/2023 15:45:32] "[35m[1mGET /joystick?data={%22x%22:5,%22y%22:-4} HTTP/1.1[0m" 500 -
13-May-23 15:45:32 - root - 87110 - INFO - {'x': 5, 'y': -10}
13-May-23 15:45:32 - root - 87110 - INFO - {'left': 1, 'right': 5}
13-May-23 15:45:32 - server - 87110 - ERROR - Exception on /joystick [GET]
Traceback (most recent call last):
  File "/Users/Aiden/anaconda3/lib/python3.9/site-packages/flask/app.py", line 2447, in wsgi_app
    response = self.full_dispatch_request()
  File "/Users/Aiden/anaconda3/lib/python3.9/site-packages/flask/app.py", line 1952, in full_dispatch_request
    rv = self.handle_user_exception(e)
  File "/Users/Aiden/anaconda3/lib/python3.9/site-packages/flask/app.py", line 1821, in handle_user_exception
    reraise(exc_type, exc_value, tb)
  File "/Users/Aiden/anaconda3/lib/python3.9/site-packages/flask/_compat.py", line 39, in reraise
    raise value
  File "/Users/Aiden/anaconda3/lib/python3.9/site-packages/flask/app.py", line 1950, in full_dispatch_request
    rv = self.dispatch_request()
  File "/Users/Aiden/anaconda3/lib/python3.9/site-packages/flask/app.py", line 1936, in dispatch_request
    return self.view_functions[rule.endpoint](**req.view_args)
  File "/Users/Aiden/Desktop/B3rryClientServer/ClientSide/server.py", line 80, in joystick
    self.motor_handler.send_motor_data(bytes(data, "utf-8"))
  File "/Users/Aiden/Desktop/B3rryClientServer/ClientSide/motorfrontend.py", line 62, in send_motor_data
    self.command_pipe.send(data)
  File "/Users/Aiden/Desktop/B3rryClientServer/ClientSide/cmdpipe.py", line 56, in send
    raise NotConnected("You must run Transmitter.connect() before attempting to send data.")
cmdpipe.NotConnected: You must run Transmitter.connect() before attempting to send data.
13-May-23 15:45:32 - werkzeug - 87110 - INFO - 127.0.0.1 - - [13/May/2023 15:45:32] "[35m[1mGET /joystick?data={%22x%22:5,%22y%22:-10} HTTP/1.1[0m" 500 -
13-May-23 15:45:32 - root - 87110 - INFO - {'x': 5, 'y': -46}
13-May-23 15:45:32 - root - 87110 - INFO - {'left': 15, 'right': 19}
13-May-23 15:45:32 - server - 87110 - ERROR - Exception on /joystick [GET]
Traceback (most recent call last):
  File "/Users/Aiden/anaconda3/lib/python3.9/site-packages/flask/app.py", line 2447, in wsgi_app
    response = self.full_dispatch_request()
  File "/Users/Aiden/anaconda3/lib/python3.9/site-packages/flask/app.py", line 1952, in full_dispatch_request
    rv = self.handle_user_exception(e)
  File "/Users/Aiden/anaconda3/lib/python3.9/site-packages/flask/app.py", line 1821, in handle_user_exception
    reraise(exc_type, exc_value, tb)
  File "/Users/Aiden/anaconda3/lib/python3.9/site-packages/flask/_compat.py", line 39, in reraise
    raise value
  File "/Users/Aiden/anaconda3/lib/python3.9/site-packages/flask/app.py", line 1950, in full_dispatch_request
    rv = self.dispatch_request()
  File "/Users/Aiden/anaconda3/lib/python3.9/site-packages/flask/app.py", line 1936, in dispatch_request
    return self.view_functions[rule.endpoint](**req.view_args)
  File "/Users/Aiden/Desktop/B3rryClientServer/ClientSide/server.py", line 80, in joystick
    self.motor_handler.send_motor_data(bytes(data, "utf-8"))
  File "/Users/Aiden/Desktop/B3rryClientServer/ClientSide/motorfrontend.py", line 62, in send_motor_data
    self.command_pipe.send(data)
  File "/Users/Aiden/Desktop/B3rryClientServer/ClientSide/cmdpipe.py", line 56, in send
    raise NotConnected("You must run Transmitter.connect() before attempting to send data.")
cmdpipe.NotConnected: You must run Transmitter.connect() before attempting to send data.
13-May-23 15:45:32 - werkzeug - 87110 - INFO - 127.0.0.1 - - [13/May/2023 15:45:32] "[35m[1mGET /joystick?data={%22x%22:5,%22y%22:-46} HTTP/1.1[0m" 500 -
13-May-23 15:45:32 - root - 87110 - INFO - {'x': 5, 'y': -79}
13-May-23 15:45:32 - root - 87110 - INFO - {'left': 28, 'right': 32}
13-May-23 15:45:32 - server - 87110 - ERROR - Exception on /joystick [GET]
Traceback (most recent call last):
  File "/Users/Aiden/anaconda3/lib/python3.9/site-packages/flask/app.py", line 2447, in wsgi_app
    response = self.full_dispatch_request()
  File "/Users/Aiden/anaconda3/lib/python3.9/site-packages/flask/app.py", line 1952, in full_dispatch_request
    rv = self.handle_user_exception(e)
  File "/Users/Aiden/anaconda3/lib/python3.9/site-packages/flask/app.py", line 1821, in handle_user_exception
    reraise(exc_type, exc_value, tb)
  File "/Users/Aiden/anaconda3/lib/python3.9/site-packages/flask/_compat.py", line 39, in reraise
    raise value
  File "/Users/Aiden/anaconda3/lib/python3.9/site-packages/flask/app.py", line 1950, in full_dispatch_request
    rv = self.dispatch_request()
  File "/Users/Aiden/anaconda3/lib/python3.9/site-packages/flask/app.py", line 1936, in dispatch_request
    return self.view_functions[rule.endpoint](**req.view_args)
  File "/Users/Aiden/Desktop/B3rryClientServer/ClientSide/server.py", line 80, in joystick
    self.motor_handler.send_motor_data(bytes(data, "utf-8"))
  File "/Users/Aiden/Desktop/B3rryClientServer/ClientSide/motorfrontend.py", line 62, in send_motor_data
    self.command_pipe.send(data)
  File "/Users/Aiden/Desktop/B3rryClientServer/ClientSide/cmdpipe.py", line 56, in send
    raise NotConnected("You must run Transmitter.connect() before attempting to send data.")
cmdpipe.NotConnected: You must run Transmitter.connect() before attempting to send data.
13-May-23 15:45:32 - werkzeug - 87110 - INFO - 127.0.0.1 - - [13/May/2023 15:45:32] "[35m[1mGET /joystick?data={%22x%22:5,%22y%22:-79} HTTP/1.1[0m" 500 -
13-May-23 15:45:33 - root - 87110 - INFO - {'x': 4.896081862546382, 'y': -99.88006999594688}
13-May-23 15:45:33 - root - 87110 - INFO - {'left': 36, 'right': 40}
13-May-23 15:45:33 - server - 87110 - ERROR - Exception on /joystick [GET]
Traceback (most recent call last):
  File "/Users/Aiden/anaconda3/lib/python3.9/site-packages/flask/app.py", line 2447, in wsgi_app
    response = self.full_dispatch_request()
  File "/Users/Aiden/anaconda3/lib/python3.9/site-packages/flask/app.py", line 1952, in full_dispatch_request
    rv = self.handle_user_exception(e)
  File "/Users/Aiden/anaconda3/lib/python3.9/site-packages/flask/app.py", line 1821, in handle_user_exception
    reraise(exc_type, exc_value, tb)
  File "/Users/Aiden/anaconda3/lib/python3.9/site-packages/flask/_compat.py", line 39, in reraise
    raise value
  File "/Users/Aiden/anaconda3/lib/python3.9/site-packages/flask/app.py", line 1950, in full_dispatch_request
    rv = self.dispatch_request()
  File "/Users/Aiden/anaconda3/lib/python3.9/site-packages/flask/app.py", line 1936, in dispatch_request
    return self.view_functions[rule.endpoint](**req.view_args)
  File "/Users/Aiden/Desktop/B3rryClientServer/ClientSide/server.py", line 80, in joystick
    self.motor_handler.send_motor_data(bytes(data, "utf-8"))
  File "/Users/Aiden/Desktop/B3rryClientServer/ClientSide/motorfrontend.py", line 62, in send_motor_data
    self.command_pipe.send(data)
  File "/Users/Aiden/Desktop/B3rryClientServer/ClientSide/cmdpipe.py", line 56, in send
    raise NotConnected("You must run Transmitter.connect() before attempting to send data.")
cmdpipe.NotConnected: You must run Transmitter.connect() before attempting to send data.
13-May-23 15:45:33 - werkzeug - 87110 - INFO - 127.0.0.1 - - [13/May/2023 15:45:33] "[35m[1mGET /joystick?data={%22x%22:4.896081862546382,%22y%22:-99.88006999594688} HTTP/1.1[0m" 500 -
13-May-23 15:45:33 - root - 87110 - INFO - {'x': 4.42045354765601, 'y': -99.90225017702562}
13-May-23 15:45:33 - root - 87110 - INFO - {'left': 36, 'right': 40}
13-May-23 15:45:33 - werkzeug - 87110 - INFO - 127.0.0.1 - - [13/May/2023 15:45:33] "GET /joystick?data={%22x%22:4.42045354765601,%22y%22:-99.90225017702562} HTTP/1.1" 200 -
13-May-23 15:45:33 - root - 87110 - INFO - {'x': 4.343722427630681, 'y': -99.90561583550596}
13-May-23 15:45:33 - root - 87110 - INFO - {'left': 36, 'right': 40}
13-May-23 15:45:33 - werkzeug - 87110 - INFO - 127.0.0.1 - - [13/May/2023 15:45:33] "GET /joystick?data={%22x%22:4.343722427630681,%22y%22:-99.90561583550596} HTTP/1.1" 200 -
13-May-23 15:45:33 - root - 87110 - INFO - {'x': 0, 'y': 0}
13-May-23 15:45:33 - root - 87110 - INFO - {'left': 0, 'right': 0}
13-May-23 15:45:33 - server - 87110 - ERROR - Exception on /joystick [GET]
Traceback (most recent call last):
  File "/Users/Aiden/anaconda3/lib/python3.9/site-packages/flask/app.py", line 2447, in wsgi_app
    response = self.full_dispatch_request()
  File "/Users/Aiden/anaconda3/lib/python3.9/site-packages/flask/app.py", line 1952, in full_dispatch_request
    rv = self.handle_user_exception(e)
  File "/Users/Aiden/anaconda3/lib/python3.9/site-packages/flask/app.py", line 1821, in handle_user_exception
    reraise(exc_type, exc_value, tb)
  File "/Users/Aiden/anaconda3/lib/python3.9/site-packages/flask/_compat.py", line 39, in reraise
    raise value
  File "/Users/Aiden/anaconda3/lib/python3.9/site-packages/flask/app.py", line 1950, in full_dispatch_request
    rv = self.dispatch_request()
  File "/Users/Aiden/anaconda3/lib/python3.9/site-packages/flask/app.py", line 1936, in dispatch_request
    return self.view_functions[rule.endpoint](**req.view_args)
  File "/Users/Aiden/Desktop/B3rryClientServer/ClientSide/server.py", line 80, in joystick
    self.motor_handler.send_motor_data(bytes(data, "utf-8"))
  File "/Users/Aiden/Desktop/B3rryClientServer/ClientSide/motorfrontend.py", line 62, in send_motor_data
    self.command_pipe.send(data)
  File "/Users/Aiden/Desktop/B3rryClientServer/ClientSide/cmdpipe.py", line 56, in send
    raise NotConnected("You must run Transmitter.connect() before attempting to send data.")
cmdpipe.NotConnected: You must run Transmitter.connect() before attempting to send data.
13-May-23 15:45:33 - werkzeug - 87110 - INFO - 127.0.0.1 - - [13/May/2023 15:45:33] "[35m[1mGET /joystick?data={%22x%22:0,%22y%22:0} HTTP/1.1[0m" 500 -
13-May-23 17:12:12 - root - 92218 - INFO - Starting server...
13-May-23 17:12:12 - root - 92218 - INFO - Preparing to client server on localhost:8080...
13-May-23 17:12:12 - root - 92218 - INFO - Server thread started!
13-May-23 17:12:12 - werkzeug - 92218 - INFO -  * Running on http://localhost:8080/ (Press CTRL+C to quit)
13-May-23 17:12:15 - werkzeug - 92218 - INFO - 127.0.0.1 - - [13/May/2023 17:12:15] "GET / HTTP/1.1" 200 -
13-May-23 17:12:20 - root - 92218 - INFO - Preparing to send connect_data_request to localhost:40000...
13-May-23 17:12:20 - werkzeug - 92218 - INFO - 127.0.0.1 - - [13/May/2023 17:12:20] "GET /connect?ip=localhost&port=40000 HTTP/1.1" 200 -
13-May-23 17:14:21 - root - 92369 - INFO - Starting server...
13-May-23 17:14:21 - root - 92369 - INFO - Preparing to client server on localhost:8080...
13-May-23 17:14:21 - root - 92369 - INFO - Server thread started!
13-May-23 17:14:21 - werkzeug - 92369 - INFO -  * Running on http://localhost:8080/ (Press CTRL+C to quit)
13-May-23 17:14:23 - werkzeug - 92369 - INFO - 127.0.0.1 - - [13/May/2023 17:14:23] "GET / HTTP/1.1" 200 -
13-May-23 17:14:23 - werkzeug - 92369 - INFO - 127.0.0.1 - - [13/May/2023 17:14:23] "GET /static/rspy.png HTTP/1.1" 200 -
13-May-23 17:14:29 - root - 92369 - INFO - Preparing to send connect_data_request to localhost:40000...
13-May-23 17:14:29 - werkzeug - 92369 - INFO - 127.0.0.1 - - [13/May/2023 17:14:29] "GET /connect?ip=localhost&port=40000 HTTP/1.1" 200 -
13-May-23 17:14:34 - root - 92369 - ERROR - Sending or recieving heartbeat timed out!
13-May-23 17:14:39 - root - 92369 - ERROR - Sending or recieving heartbeat timed out!
13-May-23 17:14:44 - root - 92369 - ERROR - Sending or recieving heartbeat timed out!
13-May-23 17:14:49 - root - 92369 - ERROR - Sending or recieving heartbeat timed out!
13-May-23 17:14:54 - root - 92369 - ERROR - Sending or recieving heartbeat timed out!
13-May-23 17:14:59 - root - 92369 - ERROR - Sending or recieving heartbeat timed out!
13-May-23 17:15:04 - root - 92369 - ERROR - Sending or recieving heartbeat timed out!
13-May-23 17:15:09 - root - 92369 - ERROR - Sending or recieving heartbeat timed out!
13-May-23 17:17:35 - root - 92548 - INFO - Starting server...
13-May-23 17:17:35 - root - 92548 - INFO - Preparing to client server on localhost:8080...
13-May-23 17:17:35 - root - 92548 - INFO - Server thread started!
13-May-23 17:17:35 - werkzeug - 92548 - INFO -  * Running on http://localhost:8080/ (Press CTRL+C to quit)
13-May-23 17:17:38 - werkzeug - 92548 - INFO - 127.0.0.1 - - [13/May/2023 17:17:38] "GET / HTTP/1.1" 200 -
13-May-23 17:17:42 - root - 92548 - INFO - Preparing to send connect_data_request to localhost:40000...
13-May-23 17:17:42 - werkzeug - 92548 - INFO - 127.0.0.1 - - [13/May/2023 17:17:42] "GET /connect?ip=localhost&port=40000 HTTP/1.1" 200 -
13-May-23 17:17:42 - werkzeug - 92548 - INFO - 127.0.0.1 - - [13/May/2023 17:17:42] "GET /static/nipplejs.min.js HTTP/1.1" 200 -
